2022-07-12 15:42:39 [INFO    ] (autoreload.run_with_reloader) Watching for file changes with StatReloader
2022-07-12 15:43:10 [WARNING ] (log.log_response) Bad Request: /user/login
2022-07-12 15:43:25 [INFO    ] (autoreload.trigger_reload) C:\Users\Silver Turku\Desktop\osai\django_project\settings.py changed, reloading.
2022-07-12 15:43:26 [INFO    ] (autoreload.run_with_reloader) Watching for file changes with StatReloader
2022-07-12 15:51:37 [INFO    ] (autoreload.trigger_reload) C:\Users\Silver Turku\Desktop\osai\mainapp\views.py changed, reloading.
2022-07-12 15:51:39 [INFO    ] (autoreload.run_with_reloader) Watching for file changes with StatReloader
2022-07-12 15:52:30 [WARNING ] (log.log_response) Not Found: /api/segnalazioni/4/delete
2022-07-12 15:53:52 [INFO    ] (autoreload.trigger_reload) C:\Users\Silver Turku\Desktop\osai\mainapp\views.py changed, reloading.
2022-07-12 15:53:53 [INFO    ] (autoreload.run_with_reloader) Watching for file changes with StatReloader
2022-07-12 15:54:00 [WARNING ] (log.log_response) Not Found: /api/segnalazioni/4/delete
2022-07-12 15:54:10 [INFO    ] (autoreload.trigger_reload) C:\Users\Silver Turku\Desktop\osai\mainapp\views.py changed, reloading.
2022-07-12 15:54:11 [INFO    ] (autoreload.run_with_reloader) Watching for file changes with StatReloader
2022-07-12 15:54:16 [WARNING ] (log.log_response) Not Found: /api/segnalazioni/4/delete
2022-07-12 15:54:41 [INFO    ] (autoreload.trigger_reload) C:\Users\Silver Turku\Desktop\osai\mainapp\views.py changed, reloading.
2022-07-12 15:54:43 [INFO    ] (autoreload.run_with_reloader) Watching for file changes with StatReloader
2022-07-12 15:55:03 [INFO    ] (autoreload.trigger_reload) C:\Users\Silver Turku\Desktop\osai\mainapp\views.py changed, reloading.
2022-07-12 15:55:04 [INFO    ] (autoreload.run_with_reloader) Watching for file changes with StatReloader
2022-07-12 15:55:30 [INFO    ] (autoreload.trigger_reload) C:\Users\Silver Turku\Desktop\osai\mainapp\views.py changed, reloading.
2022-07-12 15:55:31 [INFO    ] (autoreload.run_with_reloader) Watching for file changes with StatReloader
2022-07-12 15:55:39 [INFO    ] (autoreload.trigger_reload) C:\Users\Silver Turku\Desktop\osai\mainapp\views.py changed, reloading.
2022-07-12 15:55:40 [INFO    ] (autoreload.run_with_reloader) Watching for file changes with StatReloader
2022-07-12 15:57:46 [INFO    ] (autoreload.trigger_reload) C:\Users\Silver Turku\Desktop\osai\mainapp\views.py changed, reloading.
2022-07-12 15:57:47 [INFO    ] (autoreload.run_with_reloader) Watching for file changes with StatReloader
2022-07-12 15:57:52 [INFO    ] (autoreload.trigger_reload) C:\Users\Silver Turku\Desktop\osai\mainapp\views.py changed, reloading.
2022-07-12 15:57:53 [INFO    ] (autoreload.run_with_reloader) Watching for file changes with StatReloader
2022-07-12 15:58:00 [INFO    ] (autoreload.trigger_reload) C:\Users\Silver Turku\Desktop\osai\mainapp\views.py changed, reloading.
2022-07-12 15:58:01 [INFO    ] (autoreload.run_with_reloader) Watching for file changes with StatReloader
2022-07-12 15:58:32 [WARNING ] (log.log_response) Forbidden: /user/remove/4
2022-07-13 09:49:42 [INFO    ] (autoreload.run_with_reloader) Watching for file changes with StatReloader
2022-07-13 09:53:25 [WARNING ] (log.log_response) Not Found: /api/soluzioni/disconnect/null
2022-07-13 09:54:41 [WARNING ] (log.log_response) Not Found: /api/soluzioni/disconnect/null
2022-07-13 10:07:51 [INFO    ] (autoreload.run_with_reloader) Watching for file changes with StatReloader
2022-07-13 10:08:10 [WARNING ] (log.log_response) Unauthorized: /user/detail
2022-07-13 10:08:10 [WARNING ] (log.log_response) Unauthorized: /user/detail
2022-07-13 10:08:12 [WARNING ] (log.log_response) Unauthorized: /user/detail
2022-07-13 10:11:23 [WARNING ] (log.log_response) Not Found: /api/soluzioni/disconnect/null
2022-07-13 10:11:45 [WARNING ] (log.log_response) Not Found: /api/soluzioni/disconnect/null
2022-07-13 10:11:50 [WARNING ] (log.log_response) Not Found: /api/soluzioni/disconnect/null
2022-07-13 10:11:51 [WARNING ] (log.log_response) Bad Request: /api/soluzioni/connect/10
2022-07-13 10:13:59 [WARNING ] (log.log_response) Not Found: /api/soluzioni/disconnect/null
2022-07-13 10:33:15 [WARNING ] (log.log_response) Not Found: /api/soluzioni/disconnect/null
2022-07-13 10:37:16 [WARNING ] (log.log_response) Not Found: /api/soluzioni/connect/undefined
2022-07-13 10:37:42 [WARNING ] (log.log_response) Not Found: /api/soluzioni/disconnect/null
2022-07-13 20:30:22 [INFO    ] (autoreload.run_with_reloader) Watching for file changes with StatReloader
2022-07-13 20:35:18 [WARNING ] (log.log_response) Bad Request: /user/login
2022-07-13 20:47:18 [WARNING ] (log.log_response) Not Found: /logout
2022-07-13 20:57:58 [ERROR   ] (log.log_response) Internal Server Error: /api/segnalazioni/retrive_segnalazioni/18
Traceback (most recent call last):
  File "C:\Users\rabbi\AppData\Local\Programs\Python\Python310\lib\site-packages\django\db\backends\base\base.py", line 244, in ensure_connection
    self.connect()
  File "C:\Users\rabbi\AppData\Local\Programs\Python\Python310\lib\site-packages\django\utils\asyncio.py", line 26, in inner
    return func(*args, **kwargs)
  File "C:\Users\rabbi\AppData\Local\Programs\Python\Python310\lib\site-packages\django\db\backends\base\base.py", line 225, in connect
    self.connection = self.get_new_connection(conn_params)
  File "C:\Users\rabbi\AppData\Local\Programs\Python\Python310\lib\site-packages\django\utils\asyncio.py", line 26, in inner
    return func(*args, **kwargs)
  File "C:\Users\rabbi\AppData\Local\Programs\Python\Python310\lib\site-packages\django\db\backends\mysql\base.py", line 244, in get_new_connection
    connection = Database.connect(**conn_params)
  File "C:\Users\rabbi\AppData\Local\Programs\Python\Python310\lib\site-packages\MySQLdb\__init__.py", line 123, in Connect
    return Connection(*args, **kwargs)
  File "C:\Users\rabbi\AppData\Local\Programs\Python\Python310\lib\site-packages\MySQLdb\connections.py", line 185, in __init__
    super().__init__(*args, **kwargs2)
MySQLdb._exceptions.OperationalError: (1159, 'Got timeout reading communication packets')

The above exception was the direct cause of the following exception:

Traceback (most recent call last):
  File "C:\Users\rabbi\AppData\Local\Programs\Python\Python310\lib\site-packages\django\core\handlers\exception.py", line 55, in inner
    response = get_response(request)
  File "C:\Users\rabbi\AppData\Local\Programs\Python\Python310\lib\site-packages\django\core\handlers\base.py", line 197, in _get_response
    response = wrapped_callback(request, *callback_args, **callback_kwargs)
  File "C:\Users\rabbi\AppData\Local\Programs\Python\Python310\lib\site-packages\django\views\decorators\csrf.py", line 54, in wrapped_view
    return view_func(*args, **kwargs)
  File "C:\Users\rabbi\AppData\Local\Programs\Python\Python310\lib\site-packages\django\views\generic\base.py", line 84, in view
    return self.dispatch(request, *args, **kwargs)
  File "C:\Users\rabbi\AppData\Local\Programs\Python\Python310\lib\site-packages\rest_framework\views.py", line 509, in dispatch
    response = self.handle_exception(exc)
  File "C:\Users\rabbi\AppData\Local\Programs\Python\Python310\lib\site-packages\rest_framework\views.py", line 469, in handle_exception
    self.raise_uncaught_exception(exc)
  File "C:\Users\rabbi\AppData\Local\Programs\Python\Python310\lib\site-packages\rest_framework\views.py", line 480, in raise_uncaught_exception
    raise exc
  File "C:\Users\rabbi\AppData\Local\Programs\Python\Python310\lib\site-packages\rest_framework\views.py", line 497, in dispatch
    self.initial(request, *args, **kwargs)
  File "C:\Users\rabbi\AppData\Local\Programs\Python\Python310\lib\site-packages\rest_framework\views.py", line 414, in initial
    self.perform_authentication(request)
  File "C:\Users\rabbi\AppData\Local\Programs\Python\Python310\lib\site-packages\rest_framework\views.py", line 324, in perform_authentication
    request.user
  File "C:\Users\rabbi\AppData\Local\Programs\Python\Python310\lib\site-packages\rest_framework\request.py", line 227, in user
    self._authenticate()
  File "C:\Users\rabbi\AppData\Local\Programs\Python\Python310\lib\site-packages\rest_framework\request.py", line 380, in _authenticate
    user_auth_tuple = authenticator.authenticate(self)
  File "C:\Users\rabbi\AppData\Local\Programs\Python\Python310\lib\site-packages\rest_framework\authentication.py", line 196, in authenticate
    return self.authenticate_credentials(token)
  File "C:\Users\rabbi\AppData\Local\Programs\Python\Python310\lib\site-packages\rest_framework\authentication.py", line 201, in authenticate_credentials
    token = model.objects.select_related('user').get(key=key)
  File "C:\Users\rabbi\AppData\Local\Programs\Python\Python310\lib\site-packages\django\db\models\query.py", line 492, in get
    num = len(clone)
  File "C:\Users\rabbi\AppData\Local\Programs\Python\Python310\lib\site-packages\django\db\models\query.py", line 302, in __len__
    self._fetch_all()
  File "C:\Users\rabbi\AppData\Local\Programs\Python\Python310\lib\site-packages\django\db\models\query.py", line 1507, in _fetch_all
    self._result_cache = list(self._iterable_class(self))
  File "C:\Users\rabbi\AppData\Local\Programs\Python\Python310\lib\site-packages\django\db\models\query.py", line 57, in __iter__
    results = compiler.execute_sql(
  File "C:\Users\rabbi\AppData\Local\Programs\Python\Python310\lib\site-packages\django\db\models\sql\compiler.py", line 1359, in execute_sql
    cursor = self.connection.cursor()
  File "C:\Users\rabbi\AppData\Local\Programs\Python\Python310\lib\site-packages\django\utils\asyncio.py", line 26, in inner
    return func(*args, **kwargs)
  File "C:\Users\rabbi\AppData\Local\Programs\Python\Python310\lib\site-packages\django\db\backends\base\base.py", line 284, in cursor
    return self._cursor()
  File "C:\Users\rabbi\AppData\Local\Programs\Python\Python310\lib\site-packages\django\db\backends\base\base.py", line 260, in _cursor
    self.ensure_connection()
  File "C:\Users\rabbi\AppData\Local\Programs\Python\Python310\lib\site-packages\django\utils\asyncio.py", line 26, in inner
    return func(*args, **kwargs)
  File "C:\Users\rabbi\AppData\Local\Programs\Python\Python310\lib\site-packages\django\db\backends\base\base.py", line 243, in ensure_connection
    with self.wrap_database_errors:
  File "C:\Users\rabbi\AppData\Local\Programs\Python\Python310\lib\site-packages\django\db\utils.py", line 91, in __exit__
    raise dj_exc_value.with_traceback(traceback) from exc_value
  File "C:\Users\rabbi\AppData\Local\Programs\Python\Python310\lib\site-packages\django\db\backends\base\base.py", line 244, in ensure_connection
    self.connect()
  File "C:\Users\rabbi\AppData\Local\Programs\Python\Python310\lib\site-packages\django\utils\asyncio.py", line 26, in inner
    return func(*args, **kwargs)
  File "C:\Users\rabbi\AppData\Local\Programs\Python\Python310\lib\site-packages\django\db\backends\base\base.py", line 225, in connect
    self.connection = self.get_new_connection(conn_params)
  File "C:\Users\rabbi\AppData\Local\Programs\Python\Python310\lib\site-packages\django\utils\asyncio.py", line 26, in inner
    return func(*args, **kwargs)
  File "C:\Users\rabbi\AppData\Local\Programs\Python\Python310\lib\site-packages\django\db\backends\mysql\base.py", line 244, in get_new_connection
    connection = Database.connect(**conn_params)
  File "C:\Users\rabbi\AppData\Local\Programs\Python\Python310\lib\site-packages\MySQLdb\__init__.py", line 123, in Connect
    return Connection(*args, **kwargs)
  File "C:\Users\rabbi\AppData\Local\Programs\Python\Python310\lib\site-packages\MySQLdb\connections.py", line 185, in __init__
    super().__init__(*args, **kwargs2)
django.db.utils.OperationalError: (1159, 'Got timeout reading communication packets')
2022-07-13 20:57:58 [ERROR   ] (log.log_response) Internal Server Error: /api/occorrenze/retrive_occorrenze
Traceback (most recent call last):
  File "C:\Users\rabbi\AppData\Local\Programs\Python\Python310\lib\site-packages\django\db\backends\base\base.py", line 244, in ensure_connection
    self.connect()
  File "C:\Users\rabbi\AppData\Local\Programs\Python\Python310\lib\site-packages\django\utils\asyncio.py", line 26, in inner
    return func(*args, **kwargs)
  File "C:\Users\rabbi\AppData\Local\Programs\Python\Python310\lib\site-packages\django\db\backends\base\base.py", line 225, in connect
    self.connection = self.get_new_connection(conn_params)
  File "C:\Users\rabbi\AppData\Local\Programs\Python\Python310\lib\site-packages\django\utils\asyncio.py", line 26, in inner
    return func(*args, **kwargs)
  File "C:\Users\rabbi\AppData\Local\Programs\Python\Python310\lib\site-packages\django\db\backends\mysql\base.py", line 244, in get_new_connection
    connection = Database.connect(**conn_params)
  File "C:\Users\rabbi\AppData\Local\Programs\Python\Python310\lib\site-packages\MySQLdb\__init__.py", line 123, in Connect
    return Connection(*args, **kwargs)
  File "C:\Users\rabbi\AppData\Local\Programs\Python\Python310\lib\site-packages\MySQLdb\connections.py", line 227, in __init__
    self.autocommit(autocommit)
  File "C:\Users\rabbi\AppData\Local\Programs\Python\Python310\lib\site-packages\MySQLdb\connections.py", line 239, in autocommit
    _mysql.connection.autocommit(self, on)
MySQLdb._exceptions.OperationalError: (2013, 'Lost connection to server during query')

The above exception was the direct cause of the following exception:

Traceback (most recent call last):
  File "C:\Users\rabbi\AppData\Local\Programs\Python\Python310\lib\site-packages\django\core\handlers\exception.py", line 55, in inner
    response = get_response(request)
  File "C:\Users\rabbi\AppData\Local\Programs\Python\Python310\lib\site-packages\django\core\handlers\base.py", line 197, in _get_response
    response = wrapped_callback(request, *callback_args, **callback_kwargs)
  File "C:\Users\rabbi\AppData\Local\Programs\Python\Python310\lib\site-packages\django\views\decorators\csrf.py", line 54, in wrapped_view
    return view_func(*args, **kwargs)
  File "C:\Users\rabbi\AppData\Local\Programs\Python\Python310\lib\site-packages\django\views\generic\base.py", line 84, in view
    return self.dispatch(request, *args, **kwargs)
  File "C:\Users\rabbi\AppData\Local\Programs\Python\Python310\lib\site-packages\rest_framework\views.py", line 509, in dispatch
    response = self.handle_exception(exc)
  File "C:\Users\rabbi\AppData\Local\Programs\Python\Python310\lib\site-packages\rest_framework\views.py", line 469, in handle_exception
    self.raise_uncaught_exception(exc)
  File "C:\Users\rabbi\AppData\Local\Programs\Python\Python310\lib\site-packages\rest_framework\views.py", line 480, in raise_uncaught_exception
    raise exc
  File "C:\Users\rabbi\AppData\Local\Programs\Python\Python310\lib\site-packages\rest_framework\views.py", line 497, in dispatch
    self.initial(request, *args, **kwargs)
  File "C:\Users\rabbi\AppData\Local\Programs\Python\Python310\lib\site-packages\rest_framework\views.py", line 414, in initial
    self.perform_authentication(request)
  File "C:\Users\rabbi\AppData\Local\Programs\Python\Python310\lib\site-packages\rest_framework\views.py", line 324, in perform_authentication
    request.user
  File "C:\Users\rabbi\AppData\Local\Programs\Python\Python310\lib\site-packages\rest_framework\request.py", line 227, in user
    self._authenticate()
  File "C:\Users\rabbi\AppData\Local\Programs\Python\Python310\lib\site-packages\rest_framework\request.py", line 380, in _authenticate
    user_auth_tuple = authenticator.authenticate(self)
  File "C:\Users\rabbi\AppData\Local\Programs\Python\Python310\lib\site-packages\rest_framework\authentication.py", line 196, in authenticate
    return self.authenticate_credentials(token)
  File "C:\Users\rabbi\AppData\Local\Programs\Python\Python310\lib\site-packages\rest_framework\authentication.py", line 201, in authenticate_credentials
    token = model.objects.select_related('user').get(key=key)
  File "C:\Users\rabbi\AppData\Local\Programs\Python\Python310\lib\site-packages\django\db\models\query.py", line 492, in get
    num = len(clone)
  File "C:\Users\rabbi\AppData\Local\Programs\Python\Python310\lib\site-packages\django\db\models\query.py", line 302, in __len__
    self._fetch_all()
  File "C:\Users\rabbi\AppData\Local\Programs\Python\Python310\lib\site-packages\django\db\models\query.py", line 1507, in _fetch_all
    self._result_cache = list(self._iterable_class(self))
  File "C:\Users\rabbi\AppData\Local\Programs\Python\Python310\lib\site-packages\django\db\models\query.py", line 57, in __iter__
    results = compiler.execute_sql(
  File "C:\Users\rabbi\AppData\Local\Programs\Python\Python310\lib\site-packages\django\db\models\sql\compiler.py", line 1359, in execute_sql
    cursor = self.connection.cursor()
  File "C:\Users\rabbi\AppData\Local\Programs\Python\Python310\lib\site-packages\django\utils\asyncio.py", line 26, in inner
    return func(*args, **kwargs)
  File "C:\Users\rabbi\AppData\Local\Programs\Python\Python310\lib\site-packages\django\db\backends\base\base.py", line 284, in cursor
    return self._cursor()
  File "C:\Users\rabbi\AppData\Local\Programs\Python\Python310\lib\site-packages\django\db\backends\base\base.py", line 260, in _cursor
    self.ensure_connection()
  File "C:\Users\rabbi\AppData\Local\Programs\Python\Python310\lib\site-packages\django\utils\asyncio.py", line 26, in inner
    return func(*args, **kwargs)
  File "C:\Users\rabbi\AppData\Local\Programs\Python\Python310\lib\site-packages\django\db\backends\base\base.py", line 243, in ensure_connection
    with self.wrap_database_errors:
  File "C:\Users\rabbi\AppData\Local\Programs\Python\Python310\lib\site-packages\django\db\utils.py", line 91, in __exit__
    raise dj_exc_value.with_traceback(traceback) from exc_value
  File "C:\Users\rabbi\AppData\Local\Programs\Python\Python310\lib\site-packages\django\db\backends\base\base.py", line 244, in ensure_connection
    self.connect()
  File "C:\Users\rabbi\AppData\Local\Programs\Python\Python310\lib\site-packages\django\utils\asyncio.py", line 26, in inner
    return func(*args, **kwargs)
  File "C:\Users\rabbi\AppData\Local\Programs\Python\Python310\lib\site-packages\django\db\backends\base\base.py", line 225, in connect
    self.connection = self.get_new_connection(conn_params)
  File "C:\Users\rabbi\AppData\Local\Programs\Python\Python310\lib\site-packages\django\utils\asyncio.py", line 26, in inner
    return func(*args, **kwargs)
  File "C:\Users\rabbi\AppData\Local\Programs\Python\Python310\lib\site-packages\django\db\backends\mysql\base.py", line 244, in get_new_connection
    connection = Database.connect(**conn_params)
  File "C:\Users\rabbi\AppData\Local\Programs\Python\Python310\lib\site-packages\MySQLdb\__init__.py", line 123, in Connect
    return Connection(*args, **kwargs)
  File "C:\Users\rabbi\AppData\Local\Programs\Python\Python310\lib\site-packages\MySQLdb\connections.py", line 227, in __init__
    self.autocommit(autocommit)
  File "C:\Users\rabbi\AppData\Local\Programs\Python\Python310\lib\site-packages\MySQLdb\connections.py", line 239, in autocommit
    _mysql.connection.autocommit(self, on)
django.db.utils.OperationalError: (2013, 'Lost connection to server during query')
2022-07-13 20:57:58 [ERROR   ] (log.log_response) Internal Server Error: /user/detail
Traceback (most recent call last):
  File "C:\Users\rabbi\AppData\Local\Programs\Python\Python310\lib\site-packages\django\db\backends\base\base.py", line 244, in ensure_connection
    self.connect()
  File "C:\Users\rabbi\AppData\Local\Programs\Python\Python310\lib\site-packages\django\utils\asyncio.py", line 26, in inner
    return func(*args, **kwargs)
  File "C:\Users\rabbi\AppData\Local\Programs\Python\Python310\lib\site-packages\django\db\backends\base\base.py", line 225, in connect
    self.connection = self.get_new_connection(conn_params)
  File "C:\Users\rabbi\AppData\Local\Programs\Python\Python310\lib\site-packages\django\utils\asyncio.py", line 26, in inner
    return func(*args, **kwargs)
  File "C:\Users\rabbi\AppData\Local\Programs\Python\Python310\lib\site-packages\django\db\backends\mysql\base.py", line 244, in get_new_connection
    connection = Database.connect(**conn_params)
  File "C:\Users\rabbi\AppData\Local\Programs\Python\Python310\lib\site-packages\MySQLdb\__init__.py", line 123, in Connect
    return Connection(*args, **kwargs)
  File "C:\Users\rabbi\AppData\Local\Programs\Python\Python310\lib\site-packages\MySQLdb\connections.py", line 185, in __init__
    super().__init__(*args, **kwargs2)
MySQLdb._exceptions.OperationalError: (2013, "Lost connection to server at 'handshake: reading initial communication packet', system error: 0")

The above exception was the direct cause of the following exception:

Traceback (most recent call last):
  File "C:\Users\rabbi\AppData\Local\Programs\Python\Python310\lib\site-packages\django\core\handlers\exception.py", line 55, in inner
    response = get_response(request)
  File "C:\Users\rabbi\AppData\Local\Programs\Python\Python310\lib\site-packages\django\core\handlers\base.py", line 197, in _get_response
    response = wrapped_callback(request, *callback_args, **callback_kwargs)
  File "C:\Users\rabbi\AppData\Local\Programs\Python\Python310\lib\site-packages\django\views\decorators\csrf.py", line 54, in wrapped_view
    return view_func(*args, **kwargs)
  File "C:\Users\rabbi\AppData\Local\Programs\Python\Python310\lib\site-packages\django\views\generic\base.py", line 84, in view
    return self.dispatch(request, *args, **kwargs)
  File "C:\Users\rabbi\AppData\Local\Programs\Python\Python310\lib\site-packages\rest_framework\views.py", line 509, in dispatch
    response = self.handle_exception(exc)
  File "C:\Users\rabbi\AppData\Local\Programs\Python\Python310\lib\site-packages\rest_framework\views.py", line 469, in handle_exception
    self.raise_uncaught_exception(exc)
  File "C:\Users\rabbi\AppData\Local\Programs\Python\Python310\lib\site-packages\rest_framework\views.py", line 480, in raise_uncaught_exception
    raise exc
  File "C:\Users\rabbi\AppData\Local\Programs\Python\Python310\lib\site-packages\rest_framework\views.py", line 497, in dispatch
    self.initial(request, *args, **kwargs)
  File "C:\Users\rabbi\AppData\Local\Programs\Python\Python310\lib\site-packages\rest_framework\views.py", line 414, in initial
    self.perform_authentication(request)
  File "C:\Users\rabbi\AppData\Local\Programs\Python\Python310\lib\site-packages\rest_framework\views.py", line 324, in perform_authentication
    request.user
  File "C:\Users\rabbi\AppData\Local\Programs\Python\Python310\lib\site-packages\rest_framework\request.py", line 227, in user
    self._authenticate()
  File "C:\Users\rabbi\AppData\Local\Programs\Python\Python310\lib\site-packages\rest_framework\request.py", line 380, in _authenticate
    user_auth_tuple = authenticator.authenticate(self)
  File "C:\Users\rabbi\AppData\Local\Programs\Python\Python310\lib\site-packages\rest_framework\authentication.py", line 196, in authenticate
    return self.authenticate_credentials(token)
  File "C:\Users\rabbi\AppData\Local\Programs\Python\Python310\lib\site-packages\rest_framework\authentication.py", line 201, in authenticate_credentials
    token = model.objects.select_related('user').get(key=key)
  File "C:\Users\rabbi\AppData\Local\Programs\Python\Python310\lib\site-packages\django\db\models\query.py", line 492, in get
    num = len(clone)
  File "C:\Users\rabbi\AppData\Local\Programs\Python\Python310\lib\site-packages\django\db\models\query.py", line 302, in __len__
    self._fetch_all()
  File "C:\Users\rabbi\AppData\Local\Programs\Python\Python310\lib\site-packages\django\db\models\query.py", line 1507, in _fetch_all
    self._result_cache = list(self._iterable_class(self))
  File "C:\Users\rabbi\AppData\Local\Programs\Python\Python310\lib\site-packages\django\db\models\query.py", line 57, in __iter__
    results = compiler.execute_sql(
  File "C:\Users\rabbi\AppData\Local\Programs\Python\Python310\lib\site-packages\django\db\models\sql\compiler.py", line 1359, in execute_sql
    cursor = self.connection.cursor()
  File "C:\Users\rabbi\AppData\Local\Programs\Python\Python310\lib\site-packages\django\utils\asyncio.py", line 26, in inner
    return func(*args, **kwargs)
  File "C:\Users\rabbi\AppData\Local\Programs\Python\Python310\lib\site-packages\django\db\backends\base\base.py", line 284, in cursor
    return self._cursor()
  File "C:\Users\rabbi\AppData\Local\Programs\Python\Python310\lib\site-packages\django\db\backends\base\base.py", line 260, in _cursor
    self.ensure_connection()
  File "C:\Users\rabbi\AppData\Local\Programs\Python\Python310\lib\site-packages\django\utils\asyncio.py", line 26, in inner
    return func(*args, **kwargs)
  File "C:\Users\rabbi\AppData\Local\Programs\Python\Python310\lib\site-packages\django\db\backends\base\base.py", line 243, in ensure_connection
    with self.wrap_database_errors:
  File "C:\Users\rabbi\AppData\Local\Programs\Python\Python310\lib\site-packages\django\db\utils.py", line 91, in __exit__
    raise dj_exc_value.with_traceback(traceback) from exc_value
  File "C:\Users\rabbi\AppData\Local\Programs\Python\Python310\lib\site-packages\django\db\backends\base\base.py", line 244, in ensure_connection
    self.connect()
  File "C:\Users\rabbi\AppData\Local\Programs\Python\Python310\lib\site-packages\django\utils\asyncio.py", line 26, in inner
    return func(*args, **kwargs)
  File "C:\Users\rabbi\AppData\Local\Programs\Python\Python310\lib\site-packages\django\db\backends\base\base.py", line 225, in connect
    self.connection = self.get_new_connection(conn_params)
  File "C:\Users\rabbi\AppData\Local\Programs\Python\Python310\lib\site-packages\django\utils\asyncio.py", line 26, in inner
    return func(*args, **kwargs)
  File "C:\Users\rabbi\AppData\Local\Programs\Python\Python310\lib\site-packages\django\db\backends\mysql\base.py", line 244, in get_new_connection
    connection = Database.connect(**conn_params)
  File "C:\Users\rabbi\AppData\Local\Programs\Python\Python310\lib\site-packages\MySQLdb\__init__.py", line 123, in Connect
    return Connection(*args, **kwargs)
  File "C:\Users\rabbi\AppData\Local\Programs\Python\Python310\lib\site-packages\MySQLdb\connections.py", line 185, in __init__
    super().__init__(*args, **kwargs2)
django.db.utils.OperationalError: (2013, "Lost connection to server at 'handshake: reading initial communication packet', system error: 0")
2022-07-13 20:57:58 [ERROR   ] (log.log_response) Internal Server Error: /api/occorrenze/retrive_occorrenze
Traceback (most recent call last):
  File "C:\Users\rabbi\AppData\Local\Programs\Python\Python310\lib\site-packages\django\db\backends\base\base.py", line 244, in ensure_connection
    self.connect()
  File "C:\Users\rabbi\AppData\Local\Programs\Python\Python310\lib\site-packages\django\utils\asyncio.py", line 26, in inner
    return func(*args, **kwargs)
  File "C:\Users\rabbi\AppData\Local\Programs\Python\Python310\lib\site-packages\django\db\backends\base\base.py", line 225, in connect
    self.connection = self.get_new_connection(conn_params)
  File "C:\Users\rabbi\AppData\Local\Programs\Python\Python310\lib\site-packages\django\utils\asyncio.py", line 26, in inner
    return func(*args, **kwargs)
  File "C:\Users\rabbi\AppData\Local\Programs\Python\Python310\lib\site-packages\django\db\backends\mysql\base.py", line 244, in get_new_connection
    connection = Database.connect(**conn_params)
  File "C:\Users\rabbi\AppData\Local\Programs\Python\Python310\lib\site-packages\MySQLdb\__init__.py", line 123, in Connect
    return Connection(*args, **kwargs)
  File "C:\Users\rabbi\AppData\Local\Programs\Python\Python310\lib\site-packages\MySQLdb\connections.py", line 185, in __init__
    super().__init__(*args, **kwargs2)
MySQLdb._exceptions.OperationalError: (2013, "Lost connection to server at 'handshake: reading initial communication packet', system error: 0")

The above exception was the direct cause of the following exception:

Traceback (most recent call last):
  File "C:\Users\rabbi\AppData\Local\Programs\Python\Python310\lib\site-packages\django\core\handlers\exception.py", line 55, in inner
    response = get_response(request)
  File "C:\Users\rabbi\AppData\Local\Programs\Python\Python310\lib\site-packages\django\core\handlers\base.py", line 197, in _get_response
    response = wrapped_callback(request, *callback_args, **callback_kwargs)
  File "C:\Users\rabbi\AppData\Local\Programs\Python\Python310\lib\site-packages\django\views\decorators\csrf.py", line 54, in wrapped_view
    return view_func(*args, **kwargs)
  File "C:\Users\rabbi\AppData\Local\Programs\Python\Python310\lib\site-packages\django\views\generic\base.py", line 84, in view
    return self.dispatch(request, *args, **kwargs)
  File "C:\Users\rabbi\AppData\Local\Programs\Python\Python310\lib\site-packages\rest_framework\views.py", line 509, in dispatch
    response = self.handle_exception(exc)
  File "C:\Users\rabbi\AppData\Local\Programs\Python\Python310\lib\site-packages\rest_framework\views.py", line 469, in handle_exception
    self.raise_uncaught_exception(exc)
  File "C:\Users\rabbi\AppData\Local\Programs\Python\Python310\lib\site-packages\rest_framework\views.py", line 480, in raise_uncaught_exception
    raise exc
  File "C:\Users\rabbi\AppData\Local\Programs\Python\Python310\lib\site-packages\rest_framework\views.py", line 497, in dispatch
    self.initial(request, *args, **kwargs)
  File "C:\Users\rabbi\AppData\Local\Programs\Python\Python310\lib\site-packages\rest_framework\views.py", line 414, in initial
    self.perform_authentication(request)
  File "C:\Users\rabbi\AppData\Local\Programs\Python\Python310\lib\site-packages\rest_framework\views.py", line 324, in perform_authentication
    request.user
  File "C:\Users\rabbi\AppData\Local\Programs\Python\Python310\lib\site-packages\rest_framework\request.py", line 227, in user
    self._authenticate()
  File "C:\Users\rabbi\AppData\Local\Programs\Python\Python310\lib\site-packages\rest_framework\request.py", line 380, in _authenticate
    user_auth_tuple = authenticator.authenticate(self)
  File "C:\Users\rabbi\AppData\Local\Programs\Python\Python310\lib\site-packages\rest_framework\authentication.py", line 196, in authenticate
    return self.authenticate_credentials(token)
  File "C:\Users\rabbi\AppData\Local\Programs\Python\Python310\lib\site-packages\rest_framework\authentication.py", line 201, in authenticate_credentials
    token = model.objects.select_related('user').get(key=key)
  File "C:\Users\rabbi\AppData\Local\Programs\Python\Python310\lib\site-packages\django\db\models\query.py", line 492, in get
    num = len(clone)
  File "C:\Users\rabbi\AppData\Local\Programs\Python\Python310\lib\site-packages\django\db\models\query.py", line 302, in __len__
    self._fetch_all()
  File "C:\Users\rabbi\AppData\Local\Programs\Python\Python310\lib\site-packages\django\db\models\query.py", line 1507, in _fetch_all
    self._result_cache = list(self._iterable_class(self))
  File "C:\Users\rabbi\AppData\Local\Programs\Python\Python310\lib\site-packages\django\db\models\query.py", line 57, in __iter__
    results = compiler.execute_sql(
  File "C:\Users\rabbi\AppData\Local\Programs\Python\Python310\lib\site-packages\django\db\models\sql\compiler.py", line 1359, in execute_sql
    cursor = self.connection.cursor()
  File "C:\Users\rabbi\AppData\Local\Programs\Python\Python310\lib\site-packages\django\utils\asyncio.py", line 26, in inner
    return func(*args, **kwargs)
  File "C:\Users\rabbi\AppData\Local\Programs\Python\Python310\lib\site-packages\django\db\backends\base\base.py", line 284, in cursor
    return self._cursor()
  File "C:\Users\rabbi\AppData\Local\Programs\Python\Python310\lib\site-packages\django\db\backends\base\base.py", line 260, in _cursor
    self.ensure_connection()
  File "C:\Users\rabbi\AppData\Local\Programs\Python\Python310\lib\site-packages\django\utils\asyncio.py", line 26, in inner
    return func(*args, **kwargs)
  File "C:\Users\rabbi\AppData\Local\Programs\Python\Python310\lib\site-packages\django\db\backends\base\base.py", line 243, in ensure_connection
    with self.wrap_database_errors:
  File "C:\Users\rabbi\AppData\Local\Programs\Python\Python310\lib\site-packages\django\db\utils.py", line 91, in __exit__
    raise dj_exc_value.with_traceback(traceback) from exc_value
  File "C:\Users\rabbi\AppData\Local\Programs\Python\Python310\lib\site-packages\django\db\backends\base\base.py", line 244, in ensure_connection
    self.connect()
  File "C:\Users\rabbi\AppData\Local\Programs\Python\Python310\lib\site-packages\django\utils\asyncio.py", line 26, in inner
    return func(*args, **kwargs)
  File "C:\Users\rabbi\AppData\Local\Programs\Python\Python310\lib\site-packages\django\db\backends\base\base.py", line 225, in connect
    self.connection = self.get_new_connection(conn_params)
  File "C:\Users\rabbi\AppData\Local\Programs\Python\Python310\lib\site-packages\django\utils\asyncio.py", line 26, in inner
    return func(*args, **kwargs)
  File "C:\Users\rabbi\AppData\Local\Programs\Python\Python310\lib\site-packages\django\db\backends\mysql\base.py", line 244, in get_new_connection
    connection = Database.connect(**conn_params)
  File "C:\Users\rabbi\AppData\Local\Programs\Python\Python310\lib\site-packages\MySQLdb\__init__.py", line 123, in Connect
    return Connection(*args, **kwargs)
  File "C:\Users\rabbi\AppData\Local\Programs\Python\Python310\lib\site-packages\MySQLdb\connections.py", line 185, in __init__
    super().__init__(*args, **kwargs2)
django.db.utils.OperationalError: (2013, "Lost connection to server at 'handshake: reading initial communication packet', system error: 0")
2022-07-13 20:57:58 [ERROR   ] (log.log_response) Internal Server Error: /user/detail
Traceback (most recent call last):
  File "C:\Users\rabbi\AppData\Local\Programs\Python\Python310\lib\site-packages\django\db\backends\base\base.py", line 244, in ensure_connection
    self.connect()
  File "C:\Users\rabbi\AppData\Local\Programs\Python\Python310\lib\site-packages\django\utils\asyncio.py", line 26, in inner
    return func(*args, **kwargs)
  File "C:\Users\rabbi\AppData\Local\Programs\Python\Python310\lib\site-packages\django\db\backends\base\base.py", line 225, in connect
    self.connection = self.get_new_connection(conn_params)
  File "C:\Users\rabbi\AppData\Local\Programs\Python\Python310\lib\site-packages\django\utils\asyncio.py", line 26, in inner
    return func(*args, **kwargs)
  File "C:\Users\rabbi\AppData\Local\Programs\Python\Python310\lib\site-packages\django\db\backends\mysql\base.py", line 244, in get_new_connection
    connection = Database.connect(**conn_params)
  File "C:\Users\rabbi\AppData\Local\Programs\Python\Python310\lib\site-packages\MySQLdb\__init__.py", line 123, in Connect
    return Connection(*args, **kwargs)
  File "C:\Users\rabbi\AppData\Local\Programs\Python\Python310\lib\site-packages\MySQLdb\connections.py", line 185, in __init__
    super().__init__(*args, **kwargs2)
MySQLdb._exceptions.OperationalError: (2005, "Unknown server host 'db-osai-do-user-11496462-0.b.db.ondigitalocean.com' (11001)")

The above exception was the direct cause of the following exception:

Traceback (most recent call last):
  File "C:\Users\rabbi\AppData\Local\Programs\Python\Python310\lib\site-packages\django\core\handlers\exception.py", line 55, in inner
    response = get_response(request)
  File "C:\Users\rabbi\AppData\Local\Programs\Python\Python310\lib\site-packages\django\core\handlers\base.py", line 197, in _get_response
    response = wrapped_callback(request, *callback_args, **callback_kwargs)
  File "C:\Users\rabbi\AppData\Local\Programs\Python\Python310\lib\site-packages\django\views\decorators\csrf.py", line 54, in wrapped_view
    return view_func(*args, **kwargs)
  File "C:\Users\rabbi\AppData\Local\Programs\Python\Python310\lib\site-packages\django\views\generic\base.py", line 84, in view
    return self.dispatch(request, *args, **kwargs)
  File "C:\Users\rabbi\AppData\Local\Programs\Python\Python310\lib\site-packages\rest_framework\views.py", line 509, in dispatch
    response = self.handle_exception(exc)
  File "C:\Users\rabbi\AppData\Local\Programs\Python\Python310\lib\site-packages\rest_framework\views.py", line 469, in handle_exception
    self.raise_uncaught_exception(exc)
  File "C:\Users\rabbi\AppData\Local\Programs\Python\Python310\lib\site-packages\rest_framework\views.py", line 480, in raise_uncaught_exception
    raise exc
  File "C:\Users\rabbi\AppData\Local\Programs\Python\Python310\lib\site-packages\rest_framework\views.py", line 497, in dispatch
    self.initial(request, *args, **kwargs)
  File "C:\Users\rabbi\AppData\Local\Programs\Python\Python310\lib\site-packages\rest_framework\views.py", line 414, in initial
    self.perform_authentication(request)
  File "C:\Users\rabbi\AppData\Local\Programs\Python\Python310\lib\site-packages\rest_framework\views.py", line 324, in perform_authentication
    request.user
  File "C:\Users\rabbi\AppData\Local\Programs\Python\Python310\lib\site-packages\rest_framework\request.py", line 227, in user
    self._authenticate()
  File "C:\Users\rabbi\AppData\Local\Programs\Python\Python310\lib\site-packages\rest_framework\request.py", line 380, in _authenticate
    user_auth_tuple = authenticator.authenticate(self)
  File "C:\Users\rabbi\AppData\Local\Programs\Python\Python310\lib\site-packages\rest_framework\authentication.py", line 196, in authenticate
    return self.authenticate_credentials(token)
  File "C:\Users\rabbi\AppData\Local\Programs\Python\Python310\lib\site-packages\rest_framework\authentication.py", line 201, in authenticate_credentials
    token = model.objects.select_related('user').get(key=key)
  File "C:\Users\rabbi\AppData\Local\Programs\Python\Python310\lib\site-packages\django\db\models\query.py", line 492, in get
    num = len(clone)
  File "C:\Users\rabbi\AppData\Local\Programs\Python\Python310\lib\site-packages\django\db\models\query.py", line 302, in __len__
    self._fetch_all()
  File "C:\Users\rabbi\AppData\Local\Programs\Python\Python310\lib\site-packages\django\db\models\query.py", line 1507, in _fetch_all
    self._result_cache = list(self._iterable_class(self))
  File "C:\Users\rabbi\AppData\Local\Programs\Python\Python310\lib\site-packages\django\db\models\query.py", line 57, in __iter__
    results = compiler.execute_sql(
  File "C:\Users\rabbi\AppData\Local\Programs\Python\Python310\lib\site-packages\django\db\models\sql\compiler.py", line 1359, in execute_sql
    cursor = self.connection.cursor()
  File "C:\Users\rabbi\AppData\Local\Programs\Python\Python310\lib\site-packages\django\utils\asyncio.py", line 26, in inner
    return func(*args, **kwargs)
  File "C:\Users\rabbi\AppData\Local\Programs\Python\Python310\lib\site-packages\django\db\backends\base\base.py", line 284, in cursor
    return self._cursor()
  File "C:\Users\rabbi\AppData\Local\Programs\Python\Python310\lib\site-packages\django\db\backends\base\base.py", line 260, in _cursor
    self.ensure_connection()
  File "C:\Users\rabbi\AppData\Local\Programs\Python\Python310\lib\site-packages\django\utils\asyncio.py", line 26, in inner
    return func(*args, **kwargs)
  File "C:\Users\rabbi\AppData\Local\Programs\Python\Python310\lib\site-packages\django\db\backends\base\base.py", line 243, in ensure_connection
    with self.wrap_database_errors:
  File "C:\Users\rabbi\AppData\Local\Programs\Python\Python310\lib\site-packages\django\db\utils.py", line 91, in __exit__
    raise dj_exc_value.with_traceback(traceback) from exc_value
  File "C:\Users\rabbi\AppData\Local\Programs\Python\Python310\lib\site-packages\django\db\backends\base\base.py", line 244, in ensure_connection
    self.connect()
  File "C:\Users\rabbi\AppData\Local\Programs\Python\Python310\lib\site-packages\django\utils\asyncio.py", line 26, in inner
    return func(*args, **kwargs)
  File "C:\Users\rabbi\AppData\Local\Programs\Python\Python310\lib\site-packages\django\db\backends\base\base.py", line 225, in connect
    self.connection = self.get_new_connection(conn_params)
  File "C:\Users\rabbi\AppData\Local\Programs\Python\Python310\lib\site-packages\django\utils\asyncio.py", line 26, in inner
    return func(*args, **kwargs)
  File "C:\Users\rabbi\AppData\Local\Programs\Python\Python310\lib\site-packages\django\db\backends\mysql\base.py", line 244, in get_new_connection
    connection = Database.connect(**conn_params)
  File "C:\Users\rabbi\AppData\Local\Programs\Python\Python310\lib\site-packages\MySQLdb\__init__.py", line 123, in Connect
    return Connection(*args, **kwargs)
  File "C:\Users\rabbi\AppData\Local\Programs\Python\Python310\lib\site-packages\MySQLdb\connections.py", line 185, in __init__
    super().__init__(*args, **kwargs2)
django.db.utils.OperationalError: (2005, "Unknown server host 'db-osai-do-user-11496462-0.b.db.ondigitalocean.com' (11001)")
2022-07-13 21:09:36 [WARNING ] (log.log_response) Not Found: /media/null
2022-07-13 21:10:48 [WARNING ] (log.log_response) Not Found: /media/null
2022-07-13 21:10:52 [WARNING ] (log.log_response) Not Found: /media/null
2022-07-13 21:11:21 [WARNING ] (log.log_response) Not Found: /media/null
2022-07-13 21:11:42 [WARNING ] (log.log_response) Not Found: /media/null
2022-07-13 21:12:21 [WARNING ] (log.log_response) Not Found: /media/null
2022-07-13 21:13:11 [WARNING ] (log.log_response) Not Found: /media/null
2022-07-13 21:13:57 [WARNING ] (log.log_response) Not Found: /media/null
2022-07-13 21:13:59 [WARNING ] (log.log_response) Not Found: /media/null
2022-07-13 21:14:12 [WARNING ] (log.log_response) Not Found: /media/null
2022-07-13 21:14:14 [WARNING ] (log.log_response) Not Found: /media/null
2022-07-13 21:14:26 [WARNING ] (log.log_response) Not Found: /media/null
2022-07-13 21:15:05 [WARNING ] (log.log_response) Not Found: /media/null
2022-07-13 21:15:11 [WARNING ] (log.log_response) Not Found: /media/null
